Workbook

Sheet Matriz
B2: DAIPUNTOS — Reglas de evaluación
B3: Las celdas en azul son las únicas editables. Todo lo demás son fórmulas.
B5: 1. PUNTOS BASE = IMPACTO × ALCANCE
B6: Impacto \ Alcance | C6: 1 Estación | D6: 2 Línea / Área | E6: 3 Multi-línea / planta
B7: 1 Orden / Visual | C7: 50 | D7: 100 | E7: 150
B8: 2 Tiempo / Retrabajo | C8: 100 | D8: 200 | E8: 300
B9: 3 Calidad / Seguridad | C9: 150 | D9: 300 | E9: 450
B11: 2. AHORRO — NO da puntos en DaiPuntos
B12: Ahorro anual MXN (desde) | C12: Puntos
B13: 0 | C13: 300
B14: 10000 | C14: 500
B15: 50000 | C15: 700
B16: 150000 | C16: 1000
B17: Los Kaizen con ahorro validado se reconocen en el SALÓN DEL AHORRO (hoja aparte), no con puntos.
B19: 3. BONOS
B20: Impacto en seguridad (automático si el indicador incluye 'Seguridad') | C20: 100
B21: Idea de operador — requiere campo nuevo en el Forms | C21: 50
B22: Ya replicada en otra área — requiere campo nuevo en el Forms | C22: 50
B23: Usó herramienta de mejora — requiere campo nuevo en el Forms | C23: 50
B24: Tope de bonos | C24: 200
B26: 4. SUPUESTOS
B27: Tipo de cambio (MXN por USD) — solo para convertir a mano un Kaizen capturado en USD | C27: 17
B28: La columna 'Ahorro MXN/año' de la hoja Evaluación se captura YA EN PESOS. Si el formato del Kaizen viene en USD, multiplícalo por este tipo de cambio antes de capturarlo.
B29: Meta: 420 Kaizen/año (35/mes) — ritmo real jun-ago fue 29/mes
B30: Niveles anuales: Bronce <600 · Plata 600-1,499 · Oro 1,500-2,499 · Platino 2,500+

Sheet Evaluación
A1: EVALUACIÓN DE KAIZEN — DaiPuntos
A2: DaiPuntos = matriz + bonos. El ahorro NO da puntos aquí: los proyectos con ahorro van al Salón del Ahorro (hoja aparte).
A4: ID | B4: Fecha impl. | C4: Mes | D4: Líder (persona que cuenta) | E4: Planta | F4: Departamento | G4: Categoría (principal) | H4: IMPACTO | I4: ALCANCE | J4: Ahorro MXN/año | K4: Pts matriz | L4: Pts ahorro (informativo) | M4: Bono seg. | N4: TOTAL | O4: Revisar | P4: Problema | Q4: Mejora | R4: Registró en el Form | S4: Indicadores marcados en el Form | T4: Archivo fuente | U4: Nómina
A5: 1 | B5: 2026-05-06 | C5: 2026-05 | D5: Genet Campos (registro de prueba) | E5: Planta 1 | F5: (inválido) | G5: Seguridad | H5: 3 | I5: 2 | K5: =INDEX(Matriz!$C$7:$E$9,H5,I5) -> 300 | L5: =IF(J5="",0,IF(J5<Matriz!$B$14,Matriz!$C$13,IF(J5<Matriz!$B$15,Matriz!$C$14,IF(J5<Matriz!$B$16,Matriz!$C$15,Matriz!$C$16)))) -> 0 | M5: =IF(ISNUMBER(SEARCH("Seguridad",S5)),Matriz!$C$20,0) -> 100 | N5: =K5+MIN(M5,Matriz!$C$24) -> 400 | O5: Registro de prueba del administrador — no cuenta. | P5: sd | Q5: df | R5: Genet Campos | S5: Seguridad
A6: 2 | B6: 2026-04-01 | C6: 2026-04 | D6: Karina Guadalupe Flores González | E6: Parras | F6: Compras | G6: Ahorro | H6: 3 | I6: 3 | K6: =INDEX(Matriz!$C$7:$E$9,H6,I6) -> 450 | L6: =IF(J6="",0,IF(J6<Matriz!$B$14,Matriz!$C$13,IF(J6<Matriz!$B$15,Matriz!$C$14,IF(J6<Matriz!$B$16,Matriz!$C$15,Matriz!$C$16)))) -> 0 | M6: =IF(ISNUMBER(SEARCH("Seguridad",S6)),Matriz!$C$20,0) -> 0 | N6: =K6+MIN(M6,Matriz!$C$24) -> 450 | O6: Descripción de la mejora vacía ('.') | P6: Negociación en costo por recoleccion | Q6: . | R6: Karina Guadalupe Flores Gonzalez | S6: Ahorro $ | T6: FM-MOP-0023-DR Formato de Kaizen -R3_Karina Guadalupe Flo.xlsx | U6: 3061818
A7: 3 | B7: 2026-05-20 | C7: 2026-05 | D7: Idalia Recio | E7: Planta 3/4 | F7: Calidad | G7: Medio Ambiente | H7: 1 | I7: 3 | K7: =INDEX(Matriz!$C$7:$E$9,H7,I7) -> 150 | L7: =IF(J7="",0,IF(J7<Matriz!$B$14,Matriz!$C$13,IF(J7<Matriz!$B$15,Matriz!$C$14,IF(J7<Matriz!$B$16,Matriz!$C$15,Matriz!$C$16)))) -> 0 | M7: =IF(ISNUMBER(SEARCH("Seguridad",S7)),Matriz!$C$20,0) -> 0 | N7: =K7+MIN(M7,Matriz!$C$24) -> 150 | O7: Indicador dice 'Medio Ambiente' pero la mejora es de método/eficiencia | P7: Auditores de LPAs realizan su auditoria de proceso con un formato incorrecto. El cual se les rechaza, ya que no cumple con el programa a auditar correcto y nivel o capa correcto y se tiene que volver a realizar en el formato correcto. | Q7: Incluir en el correo de comunicación de LPAs el link del formato correcto a utilizar para descargarlo con un solo clic | R7: Idalia Recio | S7: Medio Ambiente | T7: Kaizen Mayo Calidad_Idalia Recio.xlsx | U7: 3051929
A8: 4 | B8: 2026-04-29 | C8: 2026-04 | D8: Tania Alejandra Lira Villarreal | E8: Planta 3/4 | F8: Logística | G8: Ahorro | H8: 3 | I8: 3 | J8: 474000 | K8: =INDEX(Matriz!$C$7:$E$9,H8,I8) -> 450 | L8: =IF(J8="",0,IF(J8<Matriz!$B$14,Matriz!$C$13,IF(J8<Matriz!$B$15,Matriz!$C$14,IF(J8<Matriz!$B$16,Matriz!$C$15,Matriz!$C$16)))) -> 1000 | M8: =IF(ISNUMBER(SEARCH("Seguridad",S8)),Matriz!$C$20,0) -> 0 | N8: =K8+MIN(M8,Matriz!$C$24) -> 450 | P8: VOLATILIDAD EN COSTOS DE RUTA | Q8: COSTOS FIJOS POR PERIODOS DE 3 MESES | R8: Tania Alejandra Lira Villarreal | S8: Ahorro $ | T8: FM-MOP-0023-DR Formato de Kaizen -R3 1 LOGIST_Tania Alejandra Lira.xlsx | U8: 3047688
A9: 5 | B9: 2026-05-24 | C9: 2026-05 | D9: Federico Alberto Obispo Florencio | E9: Planta 2 | F9: Calidad | G9: Calidad | H9: 3 | I9: 1 | J9: 438000 | K9: =INDEX(Matriz!$C$7:$E$9,H9,I9) -> 150 | L9: =IF(J9="",0,IF(J9<Matriz!$B$14,Matriz!$C$13,IF(J9<Matriz!$B$15,Matriz!$C$14,IF(J9<Matriz!$B$16,Matriz!$C$15,Matriz!$C$16)))) -> 1000 | M9: =IF(ISNUMBER(SEARCH("Seguridad",S9)),Matriz!$C$20,0) -> 0 | N9: =K9+MIN(M9,Matriz!$C$24) -> 150 | P9: No se contaba con un metodo para la inspeccion de la parte interna del cargador de rivian | Q9: Se implementa una lampara para la inspeccion visual y deteccion de presencia de componentes del cargador | R9: Jose Emmanuel Alejo Wong | S9: FTQ;Eficiencia;Tiempo Muerto | T9: FM-MOP-0023-DR Formato de Kaizen -R2 Calidad-_Jose Emmanuel Alejo.xlsx | U9: 3039850
A10: 6 | B10: 2026-05-28 | C10: 2026-05 | D10: Citlalli Ozuna | E10: Planta 3/4 | F10: Lanzamientos | G10: Seguridad | H10: 3 | I10: 1 | K10: =INDEX(Matriz!$C$7:$E$9,H10,I10) -> 150 | L10: =IF(J10="",0,IF(J10<Matriz!$B$14,Matriz!$C$13,IF(J10<Matriz!$B$15,Matriz!$C$14,IF(J10<Matriz!$B$16,Matriz!$C$15,Matriz!$C$16)))) -> 0 | M10: =IF(ISNUMBER(SEARCH("Seguridad",S10)),Matriz!$C$20,0) -> 100 | N10: =K10+MIN(M10,Matriz!$C$24) -> 250 | P10: Kaizen para evitar quemaduras en area de pegado de foam | Q10: Colocar un porta pistola para evitar quemaduras | R10: Citlalli Ozuna | S10: Seguridad | U10: 3039635
A11: 7 | B11: 2026-06-01 | C11: 2026-06 | D11: Maria Fernanda Tovanche | E11: Planta 1 | F11: Materiales | G11: Ahorro | H11: 3 | I11: 3 | K11: =INDEX(Matriz!$C$7:$E$9,H11,I11) -> 450 | L11: =IF(J11="",0,IF(J11<Matriz!$B$14,Matriz!$C$13,IF(J11<Matriz!$B$15,Matriz!$C$14,IF(J11<Matriz!$B$16,Matriz!$C$15,Matriz!$C$16)))) -> 0 | M11: =IF(ISNUMBER(SEARCH("Seguridad",S11)),Matriz!$C$20,0) -> 0 | N11: =K11+MIN(M11,Matriz!$C$24) -> 450 | P11: Se estaba solicitando material al proveedor HURRBARD el cual generaba un costo mensual de 5,514USD considerando el costo de la piezas y el flete logistico de forma semanal. | Q11: Cambio de proveedor a Daimay Yindai con entrega en destino, sin costo logistico. | R11: Luis Gustavo Garcia Fuentes | S11: Ahorro $ | T11: FM-MOP-0023-DR Formato de Kaizen -R3 2_Luis Gustavo Garcia.xlsx | U11: 3049161
A12: 8 | B12: 2026-07-03 | C12: 2026-07 | D12: Francisco Hernandez Ramirez | E12: Planta 2 | F12: Lanzamientos | G12: Productividad | H12: 2 | I12: 2 | K12: =INDEX(Matriz!$C$7:$E$9,H12,I12) -> 200 | L12: =IF(J12="",0,IF(J12<Matriz!$B$14,Matriz!$C$13,IF(J12<Matriz!$B$15,Matriz!$C$14,IF(J12<Matriz!$B$16,Matriz!$C$15,Matriz!$C$16)))) -> 0 | M12: =IF(ISNUMBER(SEARCH("Seguridad",S12)),Matriz!$C$20,0) -> 0 | N12: =K12+MIN(M12,Matriz!$C$24) -> 200 | P12: mal flujo de la materia prima y material terminado | Q12: creacion de un flujo de material para evitar retrazos y pedida de este | R12: Francisco Hernandez | S12: Eficiencia;5S's | T12: Kaizen_LAUNCH_JUNIO_2026_Francisco Hernandez.xlsx | U12: 3055346
A13: 9 | B13: 2026-05-18 | C13: 2026-05 | D13: Brandon Durán | E13: Planta 1 | F13: Logística | G13: Productividad | H13: 3 | I13: 3 | K13: =INDEX(Matriz!$C$7:$E$9,H13,I13) -> 450 | L13: =IF(J13="",0,IF(J13<Matriz!$B$14,Matriz!$C$13,IF(J13<Matriz!$B$15,Matriz!$C$14,IF(J13<Matriz!$B$16,Matriz!$C$15,Matriz!$C$16)))) -> 0 | M13: =IF(ISNUMBER(SEARCH("Seguridad",S13)),Matriz!$C$20,0) -> 0 | N13: =K13+MIN(M13,Matriz!$C$24) -> 450 | P13: Costos elevados de tiempo extra en aduana | Q13: Conseguir otro agente aduanal para obtener una mejor tarifa | R13: Brandon Alejandro Duran Rios | S13: Eficiencia;Ahorro $ | T13: FM-MOP-0023-DR Formato de Kaizen -R3 1 JUNIO_Brandon Alejandro Du.xlsx | U13: 3059699
A14: 10 | B14: 2026-07-02 | C14: 2026-07 | D14: Juan Carlos Guerrero Lozano | E14: Planta 2 | F14: Manufactura | G14: Seguridad | H14: 3 | I14: 2 | K14: =INDEX(Matriz!$C$7:$E$9,H14,I14) -> 300 | L14: =IF(J14="",0,IF(J14<Matriz!$B$14,Matriz!$C$13,IF(J14<Matriz!$B$15,Matriz!$C$14,IF(J14<Matriz!$B$16,Matriz!$C$15,Matriz!$C$16)))) -> 0 | M14: =IF(ISNUMBER(SEARCH("Seguridad",S14)),Matriz!$C$20,0) -> 0 | N14: =K14+MIN(M14,Matriz!$C$24) -> 300 | P14: Lineas de produccion deficientes | Q14: Colocacion de cabinas para Esprayado | R14: Carlos Lozano | S14: Eficiencia;FTQ;5S's;Ergonomía | T14: Kaizen_MFG_JUNIO_2026_Carlos Lozano.xlsx | U14: 3038990
A15: 11 | B15: 2026-07-02 | C15: 2026-07 | D15: Monica Sifuentes Ortiz | E15: Planta 2 | F15: Recursos Humanos | G15: Productividad | H15: 2 | I15: 3 | K15: =INDEX(Matriz!$C$7:$E$9,H15,I15) -> 300 | L15: =IF(J15="",0,IF(J15<Matriz!$B$14,Matriz!$C$13,IF(J15<Matriz!$B$15,Matriz!$C$14,IF(J15<Matriz!$B$16,Matriz!$C$15,Matriz!$C$16)))) -> 0 | M15: =IF(ISNUMBER(SEARCH("Seguridad",S15)),Matriz!$C$20,0) -> 0 | N15: =K15+MIN(M15,Matriz!$C$24) -> 300 | P15: Anteriormente, el reporte de transportes se llevaba en formato impreso, lo que generaba demoras en la revisión y respuesta de la información por DM. Este proceso manual incrementaba los tiempos de atención y dificultaba el acceso oportuno a los datos necesarios para la toma de decisiones. | Q15: Se implementará un código QR enlazado al correo electrónico, con el objetivo de facilitar la comunicación con el usuario y obtener su retroalimentación de manera ágil, permitiendo brindar respuestas más oportunas y mejorar el seguimiento de las solicitudes. | R15: Monica Arcelia Sifuentes Ortiz | S15: Eficiencia;Tiempo Muerto | T15: FM-MOP-0023-DR Formato de Kaizen -R3 (003)_Monica Arcelia Sifue.xlsx | U15: 3065185
A16: 12 | B16: 2026-05-25 | C16: 2026-05 | D16: Ricardo Valdivia Leyva | E16: Planta 3/4 | F16: Calidad | G16: Calidad | H16: 3 | I16: 1 | K16: =INDEX(Matriz!$C$7:$E$9,H16,I16) -> 150 | L16: =IF(J16="",0,IF(J16<Matriz!$B$14,Matriz!$C$13,IF(J16<Matriz!$B$15,Matriz!$C$14,IF(J16<Matriz!$B$16,Matriz!$C$15,Matriz!$C$16)))) -> 0 | M16: =IF(ISNUMBER(SEARCH("Seguridad",S16)),Matriz!$C$20,0) -> 0 | N16: =K16+MIN(M16,Matriz!$C$24) -> 150 | P16: Piezas fuera de especificacion | Q16: Instalacion de poka yoke mecanico | R16: Ricardo Valdivia Leyva | S16: FTQ | T16: Kaizen Calidad P3-4-Junio_Ricardo Valdivia Ley.xlsx | U16: 3029443
A17: 13 | B17: 2026-06-05 | C17: 2026-06 | D17: Ricardo Mendoza Hernandez | E17: Planta 2 | F17: Materiales | G17: Seguridad | H17: 3 | I17: 2 | K17: =INDEX(Matriz!$C$7:$E$9,H17,I17) -> 300 | L17: =IF(J17="",0,IF(J17<Matriz!$B$14,Matriz!$C$13,IF(J17<Matriz!$B$15,Matriz!$C$14,IF(J17<Matriz!$B$16,Matriz!$C$15,Matriz!$C$16)))) -> 0 | M17: =IF(ISNUMBER(SEARCH("Seguridad",S17)),Matriz!$C$20,0) -> 100 | N17: =K17+MIN(M17,Matriz!$C$24) -> 400 | P17: Racks dañados en area de empaque | Q17: Cambiar racks dañados y habilidar 16 espacios adicionales | R17: Ricardo Mendoza Hernandez | S17: Seguridad;5S's | T17: FM-MOP-0023-DR Formato de Kaizen -R3 Reemplaz_Ricardo Mendoza Hern.xlsx | U17: 3035680
A18: 14 | B18: 2026-07-17 | C18: 2026-07 | D18: (líder no identificado) | E18: Planta 6/7 | F18: Calidad | G18: Seguridad | H18: 2 | I18: 1 | K18: =INDEX(Matriz!$C$7:$E$9,H18,I18) -> 100 | L18: =IF(J18="",0,IF(J18<Matriz!$B$14,Matriz!$C$13,IF(J18<Matriz!$B$15,Matriz!$C$14,IF(J18<Matriz!$B$16,Matriz!$C$15,Matriz!$C$16)))) -> 0 | M18: =IF(ISNUMBER(SEARCH("Seguridad",S18)),Matriz!$C$20,0) -> 0 | N18: =K18+MIN(M18,Matriz!$C$24) -> 100 | O18: El campo "Nombre de líder" trae texto no válido ("Optimización del area de trabajo"). Nómina 3062914. Confirmar con quien lo registró. | P18: érdida de tiempo buscando materiales. * Riesgo de contaminación o daño del producto. * Mayor probabilidad de accidentes. * Mala imagen del área de trabajo. | Q18: instalar, asignar, retirar, ordenar, delimitar | R18: Fernanda Monserrath Vielma Zavala | S18: Ergonomía;Eficiencia;Tiempo Muerto;5S's | T18: Kaizen Mesas de inspección Cuarentena -Antoni_Fernanda Monserrath.xlsx | U18: 3062914
A19: 15 | B19: 2026-06-22 | C19: 2026-06 | D19: Felipe Angel Guerrero Herrera | E19: Planta 2 | F19: Mantenimiento | G19: Seguridad | H19: 3 | I19: 1 | K19: =INDEX(Matriz!$C$7:$E$9,H19,I19) -> 150 | L19: =IF(J19="",0,IF(J19<Matriz!$B$14,Matriz!$C$13,IF(J19<Matriz!$B$15,Matriz!$C$14,IF(J19<Matriz!$B$16,Matriz!$C$15,Matriz!$C$16)))) -> 0 | M19: =IF(ISNUMBER(SEARCH("Seguridad",S19)),Matriz!$C$20,0) -> 100 | N19: =K19+MIN(M19,Matriz!$C$24) -> 250 | P19: plancha, se baja sola al estar inoperante, con riesgo de atrapamiento a operador. | Q19: implementacion de un Shot pin de seguridad que mantenga la platina de la maquina en reposo y evite caerse aun si se queda sin energia neumatica. | R19: Felipe Angel Guerrero Herrera | S19: Seguridad | T19: Kaizen_Mtto_JUN_2026_Felipe Angel Guerrer.xlsx | U19: 3060762
A20: 16 | B20: 2026-06-30 | C20: 2026-06 | D20: Citlalli Ozuna | E20: Planta 3/4 | F20: Lanzamientos | G20: Seguridad | H20: 3 | I20: 1 | K20: =INDEX(Matriz!$C$7:$E$9,H20,I20) -> 150 | L20: =IF(J20="",0,IF(J20<Matriz!$B$14,Matriz!$C$13,IF(J20<Matriz!$B$15,Matriz!$C$14,IF(J20<Matriz!$B$16,Matriz!$C$15,Matriz!$C$16)))) -> 0 | M20: =IF(ISNUMBER(SEARCH("Seguridad",S20)),Matriz!$C$20,0) -> 100 | N20: =K20+MIN(M20,Matriz!$C$24) -> 250 | P20: Rack para coodo de materiales de ensamble en descansabrazos | Q20: colocar el ensamble de los descansabrazos; teniendo problemas de acomodo y ergonomia en el personal | R20: Citlalli Ozuna | S20: Seguridad;Ergonomía;5S's | T20: Kaizen lanzameintos Junio Planta 4_Citlalli Ozuna.xlsx | U20: 3039635
A21: 17 | B21: 2026-07-03 | C21: 2026-07 | D21: Gerardo Aguilar González | E21: Planta 1 | F21: Manufactura | G21: Productividad | H21: 2 | I21: 2 | K21: =INDEX(Matriz!$C$7:$E$9,H21,I21) -> 200 | L21: =IF(J21="",0,IF(J21<Matriz!$B$14,Matriz!$C$13,IF(J21<Matriz!$B$15,Matriz!$C$14,IF(J21<Matriz!$B$16,Matriz!$C$15,Matriz!$C$16)))) -> 0 | M21: =IF(ISNUMBER(SEARCH("Seguridad",S21)),Matriz!$C$20,0) -> 0 | N21: =K21+MIN(M21,Matriz!$C$24) -> 200 | P21: Se generaban tiempos de espera, acumulación de piezas, riesgos en las entregas por el volumen de piezas por retrabajar | Q21: se instaló una segunda pieza prensa dedicada para el porceso de retrabajo | R21: Gerardo Aguilar Gonzalez | S21: Eficiencia | T21: Kaizen Manufactura Julio 26_Gerardo Aguilar Gonz.xlsx | U21: 3060366
A22: 18 | B22: 2026-06-29 | C22: 2026-06 | D22: Mario Alberto Duron Sifuentes | E22: Planta 1 | F22: Calidad | G22: Calidad | H22: 3 | I22: 1 | K22: =INDEX(Matriz!$C$7:$E$9,H22,I22) -> 150 | L22: =IF(J22="",0,IF(J22<Matriz!$B$14,Matriz!$C$13,IF(J22<Matriz!$B$15,Matriz!$C$14,IF(J22<Matriz!$B$16,Matriz!$C$15,Matriz!$C$16)))) -> 0 | M22: =IF(ISNUMBER(SEARCH("Seguridad",S22)),Matriz!$C$20,0) -> 0 | N22: =K22+MIN(M22,Matriz!$C$24) -> 150 | P22: Camara de vision ajustada solo a un nivel de tiro corto presentado en lock tab de bracket | Q22: Se mejora el ajuste de la camara de vision con diferentes niveles de tiro corto en el lock tab del bracket, obteniendo 3 red rabbits para la liberacion del proceso y validacion de la camara de vision | R22: Mario Alberto Durón Sifuentes | S22: FTQ;Scrap | T22: Kaizen Julio 2026 Calidad Nuevo formato_Mario Alberto Durón.xlsx | U22: 3064460
A23: 19 | B23: 2026-06-29 | C23: 2026-06 | D23: Jose Isai Tostado Beltran | E23: Planta 1 | F23: Mantenimiento | G23: Productividad | H23: 3 | I23: 1 | K23: =INDEX(Matriz!$C$7:$E$9,H23,I23) -> 150 | L23: =IF(J23="",0,IF(J23<Matriz!$B$14,Matriz!$C$13,IF(J23<Matriz!$B$15,Matriz!$C$14,IF(J23<Matriz!$B$16,Matriz!$C$15,Matriz!$C$16)))) -> 0 | M23: =IF(ISNUMBER(SEARCH("Seguridad",S23)),Matriz!$C$20,0) -> 0 | N23: =K23+MIN(M23,Matriz!$C$24) -> 150 | P23: daño de secador y no se cuenta con tarjetas obsoletas no se puede reparar se realiza cambio de control y se reconecta dejando funcional secador | Q23: reparacion de control de secador | R23: Mariana Valencia | S23: Tiempo Muerto;Ahorro $ | T23: kaizen Junio 2026_Mariana Valencia.xlsx | U23: 3024217
A24: 20 | B24: 2026-07-04 | C24: 2026-07 | D24: Arturo Romo | E24: Planta 1 | F24: Manufactura | G24: Calidad | H24: 3 | I24: 1 | K24: =INDEX(Matriz!$C$7:$E$9,H24,I24) -> 150 | L24: =IF(J24="",0,IF(J24<Matriz!$B$14,Matriz!$C$13,IF(J24<Matriz!$B$15,Matriz!$C$14,IF(J24<Matriz!$B$16,Matriz!$C$15,Matriz!$C$16)))) -> 0 | M24: =IF(ISNUMBER(SEARCH("Seguridad",S24)),Matriz!$C$20,0) -> 0 | N24: =K24+MIN(M24,Matriz!$C$24) -> 150 | P24: TOLVA SE ESCARCHA DESPUES DE VARIAS CARGAS O TIEMPO | Q24: ESTABLECER UNA HORA PARA LA LIMPIEZA Y SECADO | R24: Arturo Romo Antonio | S24: Scrap;Tiempo Muerto;Eficiencia | T24: kaizen Julio 2026 Nitro_Arturo Romo Antonio.xlsx | U24: 3064592
A25: 21 | B25: 2026-06-01 | C25: 2026-06 | D25: Arsenio E Vazquez | E25: Planta 1 | F25: Calidad | G25: Calidad | H25: 3 | I25: 1 | K25: =INDEX(Matriz!$C$7:$E$9,H25,I25) -> 150 | L25: =IF(J25="",0,IF(J25<Matriz!$B$14,Matriz!$C$13,IF(J25<Matriz!$B$15,Matriz!$C$14,IF(J25<Matriz!$B$16,Matriz!$C$15,Matriz!$C$16)))) -> 0 | M25: =IF(ISNUMBER(SEARCH("Seguridad",S25)),Matriz!$C$20,0) -> 0 | N25: =K25+MIN(M25,Matriz!$C$24) -> 150 | O25: Contenido inválido: problema='Mexico', mejora=correo electrónico | P25: Mexico | Q25: evazquez@daimayus.com | R25: Arsenio Vazquez | S25: FTQ;Ahorro $ | T25: FM-MOP-0023-DR Formato de Kaizen -R3 (1)_Arsenio Vazquez.xlsx | U25: 3030820
A26: 22 | B26: 2026-07-13 | C26: 2026-07 | D26: Maximiliano Escobedo | E26: Planta 1 | F26: Lanzamientos | G26: Productividad | H26: 2 | I26: 3 | K26: =INDEX(Matriz!$C$7:$E$9,H26,I26) -> 300 | L26: =IF(J26="",0,IF(J26<Matriz!$B$14,Matriz!$C$13,IF(J26<Matriz!$B$15,Matriz!$C$14,IF(J26<Matriz!$B$16,Matriz!$C$15,Matriz!$C$16)))) -> 0 | M26: =IF(ISNUMBER(SEARCH("Seguridad",S26)),Matriz!$C$20,0) -> 0 | N26: =K26+MIN(M26,Matriz!$C$24) -> 300 | P26: No se tiene un checklist de transferencia en programas interplantas | Q26: Crear un checklist de transferencia de programas para un seguimiento puntual en las actividades a realizar | R26: Maximiliano Escobedo | S26: Eficiencia | T26: KAIZEN JULIO CHECKLIST DE TRANSFERENCIA_Maximiliano Escobedo.xlsx | U26: 3041291
A27: 23 | B27: 2026-07-14 | C27: 2026-07 | D27: Emiliano Zuñiga | E27: Planta 1 | F27: Lanzamientos | G27: Productividad | H27: 2 | I27: 2 | K27: =INDEX(Matriz!$C$7:$E$9,H27,I27) -> 200 | L27: =IF(J27="",0,IF(J27<Matriz!$B$14,Matriz!$C$13,IF(J27<Matriz!$B$15,Matriz!$C$14,IF(J27<Matriz!$B$16,Matriz!$C$15,Matriz!$C$16)))) -> 0 | M27: =IF(ISNUMBER(SEARCH("Seguridad",S27)),Matriz!$C$20,0) -> 0 | N27: =K27+MIN(M27,Matriz!$C$24) -> 200 | P27: En el área de nitrógeno, las cajas de material correspondientes a los botones se almacenan en un solo estante sin una organización definida. Actualmente se manejan más de 10 números de parte, los cuales se encuentran mezclados y sin una identificación visual clara. Esta condición dificulta que el operador o el runner localicen rápidamente el material requerido, incrementando el tiempo de búsqueda | Q27: se instalará un rack de mayor capacidad para organizar las cajas de material y asignar un espacio específico a cada número de parte. Además, se implementarán ayudas visuales mediante etiquetas y señalización para facilitar la identificación del material, reduciendo el tiempo de búsqueda y minimizando errores en el abastecimiento. | R27: Fannie Grettelle Aguilar Valero | S27: Eficiencia;Tiempo Muerto;5S's | T27: FM-MOP-0023-DR Formato de Kaizen -R3_Fannie Grettelle Agu.xlsx | U27: 3063949
A28: 24 | B28: 2026-07-10 | C28: 2026-07 | D28: Jose Isai Tostado Beltran | E28: Planta 1 | F28: Mantenimiento | G28: Ahorro | H28: 3 | I28: 2 | K28: =INDEX(Matriz!$C$7:$E$9,H28,I28) -> 300 | L28: =IF(J28="",0,IF(J28<Matriz!$B$14,Matriz!$C$13,IF(J28<Matriz!$B$15,Matriz!$C$14,IF(J28<Matriz!$B$16,Matriz!$C$15,Matriz!$C$16)))) -> 0 | M28: =IF(ISNUMBER(SEARCH("Seguridad",S28)),Matriz!$C$20,0) -> 0 | N28: =K28+MIN(M28,Matriz!$C$24) -> 300 | P28: Llegada de maquinas de inyeccion se necesita hacer espacio y facilidades | Q28: Movimiento de 2 maquinas 714 y 715 de 160 toneladas a nueva locacion para hacer espacio e instalar maquinas nuevas que mandaran de china realizacion de bajadas elecricas de agua de aire conexion de maquina nivelacion y pruebas de funcionamiento. | R28: Mariana Valencia | S28: Ahorro $ | T28: kaizen julio 2026_Mariana Valencia.xlsx | U28: 3024217
A29: 25 | B29: 2026-07-10 | C29: 2026-07 | D29: José Gerardo Gudiño Ruiz | E29: Planta 1 | F29: Cenzontle No. 7 Parque Industrial Finsa Ramos Arizpe, Coahuila, Mexico. | G29: Seguridad | H29: 3 | I29: 2 | K29: =INDEX(Matriz!$C$7:$E$9,H29,I29) -> 300 | L29: =IF(J29="",0,IF(J29<Matriz!$B$14,Matriz!$C$13,IF(J29<Matriz!$B$15,Matriz!$C$14,IF(J29<Matriz!$B$16,Matriz!$C$15,Matriz!$C$16)))) -> 0 | M29: =IF(ISNUMBER(SEARCH("Seguridad",S29)),Matriz!$C$20,0) -> 100 | N29: =K29+MIN(M29,Matriz!$C$24) -> 400 | O29: La descripción trae un correo pegado antes del texto | P29: No se tenia espejo concavo en DQMC Moldeo | Q29: jgudino@daimayus.comNo se tenia visibilidad efectiva en el área, y se opto por colocar un espejo concavo para mejorar la visibiidad del transito y eliminar el riesgo de accidentes por equipo motorizado | R29: Jose Gerardo Gudiño Ruiz | S29: Seguridad | T29: FM-MOP-0023-DR Formato de Kaizen junio 26_Jose Gerardo Gudiño.xlsx
A30: 26 | B30: 2026-06-18 | C30: 2026-06 | D30: Ulises Hernandez | E30: Planta 1 | F30: Producción | G30: Calidad | H30: 3 | I30: 2 | K30: =INDEX(Matriz!$C$7:$E$9,H30,I30) -> 300 | L30: =IF(J30="",0,IF(J30<Matriz!$B$14,Matriz!$C$13,IF(J30<Matriz!$B$15,Matriz!$C$14,IF(J30<Matriz!$B$16,Matriz!$C$15,Matriz!$C$16)))) -> 0 | M30: =IF(ISNUMBER(SEARCH("Seguridad",S30)),Matriz!$C$20,0) -> 0 | N30: =K30+MIN(M30,Matriz!$C$24) -> 300 | P30: Defectos y tiempo muerto por daños de molde | Q30: Se implementan camaras de vision para prevenir daños de molde | R30: Ulises Eduardo Hernandez Perez | S30: Scrap;Tiempo Muerto | T30: FM-MOP-0023-DR Formato de Kaizen -R2 (2)_Ulises Eduardo Herna.xlsx | U30: 3055561
A31: 27 | B31: 2026-06-25 | C31: 2026-06 | D31: Saúl Antonio Gallegos Sánchez | E31: Planta 2 | F31: EHS | G31: Seguridad | H31: 3 | I31: 2 | K31: =INDEX(Matriz!$C$7:$E$9,H31,I31) -> 300 | L31: =IF(J31="",0,IF(J31<Matriz!$B$14,Matriz!$C$13,IF(J31<Matriz!$B$15,Matriz!$C$14,IF(J31<Matriz!$B$16,Matriz!$C$15,Matriz!$C$16)))) -> 0 | M31: =IF(ISNUMBER(SEARCH("Seguridad",S31)),Matriz!$C$20,0) -> 100 | N31: =K31+MIN(M31,Matriz!$C$24) -> 400 | P31: El área no cuenta con una estación lava ojos | Q31: Colocar una estación lava ojos para cualquier emergencia | R31: Saul Antonio Gallegos Sanchez | S31: Seguridad | T31: FM-MOP-0023-DR Formato de Kaizen -R3 LAVA OJO_Saul Antonio Gallego.xlsx | U31: 3030328
A32: 28 | B32: 2026-06-10 | C32: 2026-06 | D32: Monserrat Arana | E32: Planta 1 | F32: Materiales | G32: Ahorro | H32: 3 | I32: 3 | K32: =INDEX(Matriz!$C$7:$E$9,H32,I32) -> 450 | L32: =IF(J32="",0,IF(J32<Matriz!$B$14,Matriz!$C$13,IF(J32<Matriz!$B$15,Matriz!$C$14,IF(J32<Matriz!$B$16,Matriz!$C$15,Matriz!$C$16)))) -> 0 | M32: =IF(ISNUMBER(SEARCH("Seguridad",S32)),Matriz!$C$20,0) -> 0 | N32: =K32+MIN(M32,Matriz!$C$24) -> 450 | O32: Descripción muy pobre para justificar puntos ('Ahorro en cambio de proveedor') | P32: Compra de material directo | Q32: Ahorro en cambio de proveedor | R32: Luis Gustavo Garcia Fuentes | S32: Ahorro $ | T32: FM-MOP-0023-DR Formato de Kaizen - EFLEXO_Luis Gustavo Garcia.xlsx | U32: 3041429
A33: 29 | B33: 2026-07-06 | C33: 2026-07 | D33: Ruben Siller | E33: Planta 6/7 | F33: Recursos Humanos | G33: Ahorro | H33: 3 | I33: 3 | K33: =INDEX(Matriz!$C$7:$E$9,H33,I33) -> 450 | L33: =IF(J33="",0,IF(J33<Matriz!$B$14,Matriz!$C$13,IF(J33<Matriz!$B$15,Matriz!$C$14,IF(J33<Matriz!$B$16,Matriz!$C$15,Matriz!$C$16)))) -> 0 | M33: =IF(ISNUMBER(SEARCH("Seguridad",S33)),Matriz!$C$20,0) -> 0 | N33: =K33+MIN(M33,Matriz!$C$24) -> 450 | P33: Ocupacion baja en rutas de transporte de fines de semana | Q33: Reduccion de rutas de transprote para aumentar la ocupacion y disminuir costo | R33: Ruben Alejandro Siller Valverde | S33: Ahorro $ | T33: Copy of FM-MOP-0023-DR Formato de Kaizen -JUL_Ruben Alejandro Sill.xlsx | U33: 3055539
A34: 30 | B34: 2026-07-10 | C34: 2026-07 | D34: Gerardo Gudiño Ruiz | E34: Planta 1 | F34: EHS | G34: Seguridad | H34: 3 | I34: 2 | K34: =INDEX(Matriz!$C$7:$E$9,H34,I34) -> 300 | L34: =IF(J34="",0,IF(J34<Matriz!$B$14,Matriz!$C$13,IF(J34<Matriz!$B$15,Matriz!$C$14,IF(J34<Matriz!$B$16,Matriz!$C$15,Matriz!$C$16)))) -> 0 | M34: =IF(ISNUMBER(SEARCH("Seguridad",S34)),Matriz!$C$20,0) -> 100 | N34: =K34+MIN(M34,Matriz!$C$24) -> 400 | P34: Daño en tuberias de sistema lavaojos por alta dureza en el agua utilizada. | Q34: Se coloca lavaojos portatil con agua y solución de Ag para eliminar sales minerales. | R34: Jose Gerardo Gudiño Ruiz | S34: Seguridad;Medio Ambiente | U34: 3058416
A35: 31 | B35: 2026-07-06 | C35: 2026-07 | D35: Eduardo Gonzalez | E35: Planta 1 | F35: Recursos Humanos | G35: Productividad | H35: 3 | I35: 3 | K35: =INDEX(Matriz!$C$7:$E$9,H35,I35) -> 450 | L35: =IF(J35="",0,IF(J35<Matriz!$B$14,Matriz!$C$13,IF(J35<Matriz!$B$15,Matriz!$C$14,IF(J35<Matriz!$B$16,Matriz!$C$15,Matriz!$C$16)))) -> 0 | M35: =IF(ISNUMBER(SEARCH("Seguridad",S35)),Matriz!$C$20,0) -> 0 | N35: =K35+MIN(M35,Matriz!$C$24) -> 450 | P35: no se tenia para personal directo registro de vacaciones en linea | Q35: se pone kiosko con aplicacion de porwer app para que puedan acceder a pedir sus vacaciones de manera electronica | R35: Diana Themis Zacanelles Orta | S35: Eficiencia;Tiempo Muerto;Ahorro $ | T35: Formato de Kaizen RH Julio_Diana Themis Zacanel.xlsx | U35: 3029246
A36: 32 | B36: 2026-07-17 | C36: 2026-07 | D36: Saúl Antonio Gallegos Sánchez | E36: Planta 2 | F36: EHS | G36: Seguridad | H36: 3 | I36: 2 | K36: =INDEX(Matriz!$C$7:$E$9,H36,I36) -> 300 | L36: =IF(J36="",0,IF(J36<Matriz!$B$14,Matriz!$C$13,IF(J36<Matriz!$B$15,Matriz!$C$14,IF(J36<Matriz!$B$16,Matriz!$C$15,Matriz!$C$16)))) -> 0 | M36: =IF(ISNUMBER(SEARCH("Seguridad",S36)),Matriz!$C$20,0) -> 100 | N36: =K36+MIN(M36,Matriz!$C$24) -> 400 | P36: Anteriormente se usaba una cinta para cubrir sus dedos, esa cinta generaba un gasto ya que era parte del proceso de producción | Q36: Se cambia a una cinta dedal mas economica exclusiva como equipo de protección | R36: Saul Antonio Gallegos Sanchez | S36: Seguridad;Ahorro $ | T36: FM-MOP-0023-DR Formato de Kaizen -R3 Julio EH_Saul Antonio Gallego.xlsx | U36: 3030328
A37: 33 | B37: 2026-07-15 | C37: 2026-07 | D37: Francisco Hernandez Ramirez | E37: Planta 2 | F37: Lanzamientos | G37: Seguridad | H37: 3 | I37: 2 | K37: =INDEX(Matriz!$C$7:$E$9,H37,I37) -> 300 | L37: =IF(J37="",0,IF(J37<Matriz!$B$14,Matriz!$C$13,IF(J37<Matriz!$B$15,Matriz!$C$14,IF(J37<Matriz!$B$16,Matriz!$C$15,Matriz!$C$16)))) -> 0 | M37: =IF(ISNUMBER(SEARCH("Seguridad",S37)),Matriz!$C$20,0) -> 0 | N37: =K37+MIN(M37,Matriz!$C$24) -> 300 | P37: acumulado de material productivo que se empalmaba y generaba daños | Q37: se coloca un tandedero par apoder tener mejor aocmodo dle material productivo | R37: Francisco Hernandez | S37: Ergonomía;Eficiencia;Scrap;Tiempo Muerto | T37: Kaizen_LAUNCH_JULIO_2026_Francisco Hernandez.xlsx | U37: 3055346
A38: 34 | B38: 2026-07-13 | C38: 2026-07 | D38: Monica Sifuentes Ortiz | E38: Planta 2 | F38: Recursos Humanos | G38: Productividad | H38: 2 | I38: 3 | K38: =INDEX(Matriz!$C$7:$E$9,H38,I38) -> 300 | L38: =IF(J38="",0,IF(J38<Matriz!$B$14,Matriz!$C$13,IF(J38<Matriz!$B$15,Matriz!$C$14,IF(J38<Matriz!$B$16,Matriz!$C$15,Matriz!$C$16)))) -> 0 | M38: =IF(ISNUMBER(SEARCH("Seguridad",S38)),Matriz!$C$20,0) -> 0 | N38: =K38+MIN(M38,Matriz!$C$24) -> 300 | P38: El sistema agrupaba a los colaboradores en líneas de producción de forma general. Era complicado identificar con precisión el área específica donde laboraba cada empleado. Esto ocasionaba demoras al generar reportes, realizar movimientos de personal o analizar indicadores por área. | Q38: Se actualizó el catálogo de líneas y se asignó a cada colaborador el área específica donde realmente desempeña sus funciones. Se homologó la nomenclatura para evitar confusiones entre áreas. | R38: Monica Arcelia Sifuentes Ortiz | S38: Eficiencia;Tiempo Muerto | T38: FM-MOP-0023-DR Formato de Kaizen -R3 - PROPUE_Monica Arcelia Sifue.xlsx | U38: 3065185
A39: 35 | B39: 2026-07-03 | C39: 2026-07 | D39: Gerardo Rodriguez Garay | E39: Planta 1 | F39: Calidad | G39: Productividad | H39: 2 | I39: 1 | K39: =INDEX(Matriz!$C$7:$E$9,H39,I39) -> 100 | L39: =IF(J39="",0,IF(J39<Matriz!$B$14,Matriz!$C$13,IF(J39<Matriz!$B$15,Matriz!$C$14,IF(J39<Matriz!$B$16,Matriz!$C$15,Matriz!$C$16)))) -> 0 | M39: =IF(ISNUMBER(SEARCH("Seguridad",S39)),Matriz!$C$20,0) -> 0 | N39: =K39+MIN(M39,Matriz!$C$24) -> 100 | P39: Cabecera T1XX con problemas de alineacion (deformacion) | Q39: revision de piezas con pin actuador de mecanismo | R39: Gerardo Rodriguez | S39: Eficiencia | T39: Kaizen Moldeo - Julio '2026 (1)_Gerardo Rodriguez.xlsx | U39: 1616978
A40: 36 | B40: 2026-07-27 | C40: 2026-07 | D40: Juan Carlos Guerrero Lozano | E40: Planta 2 | F40: Manufactura | G40: Productividad | H40: 2 | I40: 2 | K40: =INDEX(Matriz!$C$7:$E$9,H40,I40) -> 200 | L40: =IF(J40="",0,IF(J40<Matriz!$B$14,Matriz!$C$13,IF(J40<Matriz!$B$15,Matriz!$C$14,IF(J40<Matriz!$B$16,Matriz!$C$15,Matriz!$C$16)))) -> 0 | M40: =IF(ISNUMBER(SEARCH("Seguridad",S40)),Matriz!$C$20,0) -> 0 | N40: =K40+MIN(M40,Matriz!$C$24) -> 200 | P40: Lineas de produccion deficientes | Q40: Creacion de TOOL BOOK | R40: Carlos Lozano | S40: Eficiencia;5S's | T40: Kaizen_MFG_JULIO_2026_Carlos Lozano.xlsx | U40: 3038990
A41: 37 | B41: 2026-07-20 | C41: 2026-07 | D41: Hector Velasco | E41: Planta 6/7 | F41: Manufactura | G41: Productividad | H41: 2 | I41: 1 | K41: =INDEX(Matriz!$C$7:$E$9,H41,I41) -> 100 | L41: =IF(J41="",0,IF(J41<Matriz!$B$14,Matriz!$C$13,IF(J41<Matriz!$B$15,Matriz!$C$14,IF(J41<Matriz!$B$16,Matriz!$C$15,Matriz!$C$16)))) -> 0 | M41: =IF(ISNUMBER(SEARCH("Seguridad",S41)),Matriz!$C$20,0) -> 0 | N41: =K41+MIN(M41,Matriz!$C$24) -> 100 | P41: La máquina de ensamble de botón presenta fallas recurrentes desde principios de mayo. La principal causa es el movimiento de la cámara de visión, ya que no se encuentra correctamente sujeta. Esta condición provoca falsos rechazos de piezas y paros frecuentes de la máquina, afectando la estabilidad del proceso y la productividad. | Q41: Se propone diseñar e instalar una base de soporte para asegurar la correcta fijación de la cámara de visión y eliminar su movimiento durante el ciclo de operación de la máquina. Con esta mejora se busca reducir los falsos rechazos, minimizar los paros de máquina y aumentar la eficiencia del proceso de ensamble | R41: Jennifer Garcia Gregorio | S41: Eficiencia | T41: Formato de Kaizen Manufactura P6_Jennifer Garcia Greg.xlsx | U41: 3035216
...

Sheet Resumen
A1: RESUMEN — abril a septiembre 2026
A2: Todas las cifras son fórmulas sobre la hoja Evaluación. Excluye el ID 1 (prueba).
A4: POR PLANTA
A5: Planta | B5: Kaizen | C5: DaiPuntos | D5: Promedio | E5: Meta anual* | F5: % meta
A6: Planta 1 | B6: =COUNTIFS(Evaluación!$E$5:$E$136,A6,Evaluación!$A$5:$A$136,">1") -> 32 | C6: =SUMIFS(Evaluación!$N$5:$N$136,Evaluación!$E$5:$E$136,A6,Evaluación!$A$5:$A$136,">1") -> 8050 | D6: =IF(B6=0,0,ROUND(C6/B6,0)) -> 252 | E6: 70 | F6: =IF(E6=0,0,B6/E6) -> 0.45714286
A7: Planta 2 | B7: =COUNTIFS(Evaluación!$E$5:$E$136,A7,Evaluación!$A$5:$A$136,">1") -> 38 | C7: =SUMIFS(Evaluación!$N$5:$N$136,Evaluación!$E$5:$E$136,A7,Evaluación!$A$5:$A$136,">1") -> 11650 | D7: =IF(B7=0,0,ROUND(C7/B7,0)) -> 307 | E7: 70 | F7: =IF(E7=0,0,B7/E7) -> 0.54285714
A8: Planta 3/4 | B8: =COUNTIFS(Evaluación!$E$5:$E$136,A8,Evaluación!$A$5:$A$136,">1") -> 27 | C8: =SUMIFS(Evaluación!$N$5:$N$136,Evaluación!$E$5:$E$136,A8,Evaluación!$A$5:$A$136,">1") -> 6800 | D8: =IF(B8=0,0,ROUND(C8/B8,0)) -> 252 | E8: 70 | F8: =IF(E8=0,0,B8/E8) -> 0.38571429
A9: Planta 6/7 | B9: =COUNTIFS(Evaluación!$E$5:$E$136,A9,Evaluación!$A$5:$A$136,">1") -> 19 | C9: =SUMIFS(Evaluación!$N$5:$N$136,Evaluación!$E$5:$E$136,A9,Evaluación!$A$5:$A$136,">1") -> 4400 | D9: =IF(B9=0,0,ROUND(C9/B9,0)) -> 232 | E9: 70 | F9: =IF(E9=0,0,B9/E9) -> 0.27142857
A10: Planta 8 | B10: =COUNTIFS(Evaluación!$E$5:$E$136,A10,Evaluación!$A$5:$A$136,">1") -> 0 | C10: =SUMIFS(Evaluación!$N$5:$N$136,Evaluación!$E$5:$E$136,A10,Evaluación!$A$5:$A$136,">1") -> 0 | D10: =IF(B10=0,0,ROUND(C10/B10,0)) -> 0 | E10: 70 | F10: =IF(E10=0,0,B10/E10) -> 0
A11: Parras | B11: =COUNTIFS(Evaluación!$E$5:$E$136,A11,Evaluación!$A$5:$A$136,">1") -> 10 | C11: =SUMIFS(Evaluación!$N$5:$N$136,Evaluación!$E$5:$E$136,A11,Evaluación!$A$5:$A$136,">1") -> 3400 | D11: =IF(B11=0,0,ROUND(C11/B11,0)) -> 340 | E11: 70 | F11: =IF(E11=0,0,B11/E11) -> 0.14285714
A12: TOTAL | B12: =SUM(B6:B11) -> 126 | C12: =SUM(C6:C11) -> 34300 | D12: =IF(B12=0,0,ROUND(C12/B12,0)) -> 272 | E12: =SUM(E6:E11) -> 420 | F12: =IF(E12=0,0,B12/E12) -> 0.3
A13: * Meta anual por planta = 420 Kaizen/año de la red entre 6 sitios. Ritmo real jun-ago: 29/mes.
A15: POR MES
A16: Mes | B16: Kaizen | C16: DaiPuntos | D16: Promedio | E16: Meta mensual | F16: % meta
A17: 2026-04 | B17: =COUNTIFS(Evaluación!$C$5:$C$136,A17,Evaluación!$A$5:$A$136,">1") -> 2 | C17: =SUMIFS(Evaluación!$N$5:$N$136,Evaluación!$C$5:$C$136,A17,Evaluación!$A$5:$A$136,">1") -> 900 | D17: =IF(B17=0,0,ROUND(C17/B17,0)) -> 450 | E17: 48 | F17: =IF(E17=0,0,B17/E17) -> 0.041666667
A18: 2026-05 | B18: =COUNTIFS(Evaluación!$C$5:$C$136,A18,Evaluación!$A$5:$A$136,">1") -> 7 | C18: =SUMIFS(Evaluación!$N$5:$N$136,Evaluación!$C$5:$C$136,A18,Evaluación!$A$5:$A$136,">1") -> 1550 | D18: =IF(B18=0,0,ROUND(C18/B18,0)) -> 221 | E18: 48 | F18: =IF(E18=0,0,B18/E18) -> 0.14583333
A19: 2026-06 | B19: =COUNTIFS(Evaluación!$C$5:$C$136,A19,Evaluación!$A$5:$A$136,">1") -> 14 | C19: =SUMIFS(Evaluación!$N$5:$N$136,Evaluación!$C$5:$C$136,A19,Evaluación!$A$5:$A$136,">1") -> 4050 | D19: =IF(B19=0,0,ROUND(C19/B19,0)) -> 289 | E19: 48 | F19: =IF(E19=0,0,B19/E19) -> 0.29166667
A20: 2026-07 | B20: =COUNTIFS(Evaluación!$C$5:$C$136,A20,Evaluación!$A$5:$A$136,">1") -> 43 | C20: =SUMIFS(Evaluación!$N$5:$N$136,Evaluación!$C$5:$C$136,A20,Evaluación!$A$5:$A$136,">1") -> 12200 | D20: =IF(B20=0,0,ROUND(C20/B20,0)) -> 284 | E20: 48 | F20: =IF(E20=0,0,B20/E20) -> 0.89583333
A21: 2026-08 | B21: =COUNTIFS(Evaluación!$C$5:$C$136,A21,Evaluación!$A$5:$A$136,">1") -> 34 | C21: =SUMIFS(Evaluación!$N$5:$N$136,Evaluación!$C$5:$C$136,A21,Evaluación!$A$5:$A$136,">1") -> 10150 | D21: =IF(B21=0,0,ROUND(C21/B21,0)) -> 299 | E21: 48 | F21: =IF(E21=0,0,B21/E21) -> 0.70833333
A22: 2026-09 | B22: =COUNTIFS(Evaluación!$C$5:$C$136,A22,Evaluación!$A$5:$A$136,">1") -> 28 | C22: =SUMIFS(Evaluación!$N$5:$N$136,Evaluación!$C$5:$C$136,A22,Evaluación!$A$5:$A$136,">1") -> 5550 | D22: =IF(B22=0,0,ROUND(C22/B22,0)) -> 198 | E22: 48 | F22: =IF(E22=0,0,B22/E22) -> 0.58333333
A23: Septiembre está incompleto (datos al 24-sep).
A26: POR DEPARTAMENTO (toda la red)
A27: Departamento | B27: Kaizen | C27: DaiPuntos | D27: Promedio | E27: Meta anual** | F27: % meta
A28: Calidad | B28: =COUNTIFS(Evaluación!$F$5:$F$136,A28,Evaluación!$A$5:$A$136,">1") -> 21 | C28: =SUMIFS(Evaluación!$N$5:$N$136,Evaluación!$F$5:$F$136,A28,Evaluación!$A$5:$A$136,">1") -> 4350 | D28: =IF(B28=0,0,ROUND(C28/B28,0)) -> 207 | E28: 72 | F28: =IF(E28=0,0,B28/E28) -> 0.29166667
A29: Lanzamientos | B29: =COUNTIFS(Evaluación!$F$5:$F$136,A29,Evaluación!$A$5:$A$136,">1") -> 14 | C29: =SUMIFS(Evaluación!$N$5:$N$136,Evaluación!$F$5:$F$136,A29,Evaluación!$A$5:$A$136,">1") -> 3250 | D29: =IF(B29=0,0,ROUND(C29/B29,0)) -> 232 | E29: 72 | F29: =IF(E29=0,0,B29/E29) -> 0.19444444
A30: Mantenimiento | B30: =COUNTIFS(Evaluación!$F$5:$F$136,A30,Evaluación!$A$5:$A$136,">1") -> 18 | C30: =SUMIFS(Evaluación!$N$5:$N$136,Evaluación!$F$5:$F$136,A30,Evaluación!$A$5:$A$136,">1") -> 4550 | D30: =IF(B30=0,0,ROUND(C30/B30,0)) -> 253 | E30: 72 | F30: =IF(E30=0,0,B30/E30) -> 0.25
A31: Manufactura | B31: =COUNTIFS(Evaluación!$F$5:$F$136,A31,Evaluación!$A$5:$A$136,">1") -> 15 | C31: =SUMIFS(Evaluación!$N$5:$N$136,Evaluación!$F$5:$F$136,A31,Evaluación!$A$5:$A$136,">1") -> 2500 | D31: =IF(B31=0,0,ROUND(C31/B31,0)) -> 167 | E31: 72 | F31: =IF(E31=0,0,B31/E31) -> 0.20833333
A32: EHS | B32: =COUNTIFS(Evaluación!$F$5:$F$136,A32,Evaluación!$A$5:$A$136,">1") -> 13 | C32: =SUMIFS(Evaluación!$N$5:$N$136,Evaluación!$F$5:$F$136,A32,Evaluación!$A$5:$A$136,">1") -> 4700 | D32: =IF(B32=0,0,ROUND(C32/B32,0)) -> 362 | E32: 72 | F32: =IF(E32=0,0,B32/E32) -> 0.18055556
A33: Recursos Humanos | B33: =COUNTIFS(Evaluación!$F$5:$F$136,A33,Evaluación!$A$5:$A$136,">1") -> 11 | C33: =SUMIFS(Evaluación!$N$5:$N$136,Evaluación!$F$5:$F$136,A33,Evaluación!$A$5:$A$136,">1") -> 4200 | D33: =IF(B33=0,0,ROUND(C33/B33,0)) -> 382 | E33: 72 | F33: =IF(E33=0,0,B33/E33) -> 0.15277778
A34: Materiales | B34: =COUNTIFS(Evaluación!$F$5:$F$136,A34,Evaluación!$A$5:$A$136,">1") -> 17 | C34: =SUMIFS(Evaluación!$N$5:$N$136,Evaluación!$F$5:$F$136,A34,Evaluación!$A$5:$A$136,">1") -> 4750 | D34: =IF(B34=0,0,ROUND(C34/B34,0)) -> 279 | E34: 72 | F34: =IF(E34=0,0,B34/E34) -> 0.23611111
A35: Producción | B35: =COUNTIFS(Evaluación!$F$5:$F$136,A35,Evaluación!$A$5:$A$136,">1") -> 11 | C35: =SUMIFS(Evaluación!$N$5:$N$136,Evaluación!$F$5:$F$136,A35,Evaluación!$A$5:$A$136,">1") -> 2850 | D35: =IF(B35=0,0,ROUND(C35/B35,0)) -> 259 | E35: 72 | F35: =IF(E35=0,0,B35/E35) -> 0.15277778
A36: Logística | B36: =COUNTIFS(Evaluación!$F$5:$F$136,A36,Evaluación!$A$5:$A$136,">1") -> 5 | C36: =SUMIFS(Evaluación!$N$5:$N$136,Evaluación!$F$5:$F$136,A36,Evaluación!$A$5:$A$136,">1") -> 2250 | D36: =IF(B36=0,0,ROUND(C36/B36,0)) -> 450 | E36: 72 | F36: =IF(E36=0,0,B36/E36) -> 0.069444444
A37: Operaciones | B37: =COUNTIFS(Evaluación!$F$5:$F$136,A37,Evaluación!$A$5:$A$136,">1") -> 3 | C37: =SUMIFS(Evaluación!$N$5:$N$136,Evaluación!$F$5:$F$136,A37,Evaluación!$A$5:$A$136,">1") -> 600 | D37: =IF(B37=0,0,ROUND(C37/B37,0)) -> 200 | E37: 72 | F37: =IF(E37=0,0,B37/E37) -> 0.041666667
A38: Compras | B38: =COUNTIFS(Evaluación!$F$5:$F$136,A38,Evaluación!$A$5:$A$136,">1") -> 2 | C38: =SUMIFS(Evaluación!$N$5:$N$136,Evaluación!$F$5:$F$136,A38,Evaluación!$A$5:$A$136,">1") -> 750 | D38: =IF(B38=0,0,ROUND(C38/B38,0)) -> 375 | E38: 72 | F38: =IF(E38=0,0,B38/E38) -> 0.027777778
A39: Cenzontle No. 7 Parque Industrial Finsa Ramos Arizpe, Coahuila, Mexico. | B39: =COUNTIFS(Evaluación!$F$5:$F$136,A39,Evaluación!$A$5:$A$136,">1") -> 1 | C39: =SUMIFS(Evaluación!$N$5:$N$136,Evaluación!$F$5:$F$136,A39,Evaluación!$A$5:$A$136,">1") -> 400 | D39: =IF(B39=0,0,ROUND(C39/B39,0)) -> 400 | E39: 72 | F39: =IF(E39=0,0,B39/E39) -> 0.013888889
A40: ** 6 sitios × 12 meses = 72 al año por departamento si participaran los 6.

Sheet Auditoría formatos
A1: AUDITORÍA DE LOS 91 FORMATOS FM-MOP-0023-DR
A4: RESUMEN
A5: A. Cuantificado en $ (tiene (B) Beneficio o Ahorro al año) | D5: 12 | E5: 0.13186813
A6: B. Con números en Antes/Después pero sin total en $ | D6: 29 | E6: 0.31868132
A7: C. Solo descripción de texto, cero números | D7: 42 | E7: 0.46153846
A8: D. Tabla de beneficio completamente vacía | D8: 8 | E8: 0.087912088
A9: TOTAL | D9: 91
A11: Formatos que NO marcaron el estatus (Implementada/Aprobada/…) | D11: 87
A12: Formatos que NO marcaron '¿Se puede implementar en otra área?' | D12: 64
A13: Formatos con (B) Beneficio $ numérico | D13: 12
A14: Formatos con 'Ahorro al año' lleno | D14: 1
A17: DETALLE POR KAIZEN
A18: ID | B18: Persona | C18: Planta | D18: Clase | E18: (B) Benef. | F18: (C) Costo | G18: Unidad declarada | H18: Estatus | I18: Expansión | J18: ¿Dónde? | K18: Archivo
A19: 40 | B19: Tania Alejandra Lira Villarreal | C19: Planta 6/7 | D19: A. Cuantificado en $ | E19: 474000 | F19: 552000 | G19: MXN | H19: — sin marcar | I19: — | K19: FM-MOP-0023-DR Formato de Kaizen -R3 1 LOGIST_Tania Alejandra Lira 1.xlsx
A20: 88 | B20: Tania Alejandra Lira Villarreal | C20: Planta 3/4 | D20: A. Cuantificado en $ | E20: 438000 | F20: 510000 | G20: MXN | H20: — sin marcar | I20: — | K20: FM-MOP-0023-DR Formato de Kaizen -R3 1 LOGIST_Tania Alejandra Lira 2.xlsx
A21: 96 | B21: Francisco Daniel Charles Sanchez | C21: Planta 2 | D21: A. Cuantificado en $ | E21: 437483.41 | F21: 115868.45 | G21: Evento | H21: — sin marcar | I21: — | J21: Area de Compras Indirectas | K21: FM-MOP-0023-DR Formato de Kaizen -R3 - Reducc_Francisco Daniel Cha.xlsx
A22: 91 | B22: Karla Guadalupe Padilla Gonzalez | C22: Planta 3/4 | D22: A. Cuantificado en $ | E22: 130000 | F22: 550 | G22: Total | H22: — sin marcar | I22: — | K22: FM-MOP-0023-DR Formato de Kaizen AGOSTO_Karla Guadalupe Padi.xlsx
A23: 43 | B23: Felipe Angel Guerrero Herrera | C23: Planta 2 | D23: A. Cuantificado en $ | E23: 25000 | G23: Total | H23: — sin marcar | I23: — | K23: Kaizen_Mtto_JUL_2026 Mejora_Felipe Angel Guerrer.xlsx
A24: 55 | B24: Nestor Garcia Castro Garcia Castro | C24: Planta 3/4 | D24: A. Cuantificado en $ | E24: 15800 | F24: 1000 | H24: — sin marcar | I24: — | J24: Area de UPPER | K24: Kaizen Rivian Door julio_Nestor Garcia Castr.xlsx
A25: 70 | B25: Diego Valencia Alcazar | C25: Planta 1 | D25: A. Cuantificado en $ | E25: 14000 | F25: 0 | G25: HRS | H25: — sin marcar | I25: NO | K25: Kaizen Moldeo Agosto 2026_Diego Valencia Alcaz.xlsx
A26: 7 | B26: Luis Gustavo Garcia Fuentes | C26: Planta 1 | D26: A. Cuantificado en $ | E26: 4166.96 | F26: 0 | G26: 7920.0 | H26: — sin marcar | I26: NO | K26: FM-MOP-0023-DR Formato de Kaizen -R3 2_Luis Gustavo Garcia.xlsx
A27: 97 | B27: Salome Dominguez | C27: Planta 1 | D27: A. Cuantificado en $ | E27: 499.25 | G27: % | H27: — sin marcar | I27: — | J27: Procesos donde aplique grasa | K27: FM-MOP-0023-DR Formato de Kaizen -R3_Salome Dominguez.xlsx
A28: 87 | B28: Fernando Gonzalez | C28: Planta 3/4 | D28: A. Cuantificado en $ | E28: 460.89 | F28: 0 | G28: USD | H28: — sin marcar | I28: — | K28: Calidad - P3y4 - Agosto_Fernando Gonzalez.xlsx
A29: 28 | B29: Luis Gustavo Garcia Fuentes | C29: Planta 1 | D29: A. Cuantificado en $ | E29: 430 | F29: 0 | G29: 1.0 | H29: — sin marcar | I29: NO | K29: FM-MOP-0023-DR Formato de Kaizen - EFLEXO_Luis Gustavo Garcia.xlsx
A30: 94 | B30: Fannie Grettelle Aguilar Valero | C30: Planta 1 | D30: A. Cuantificado en $ | E30: 6.73 | F30: 0.6 | G30: USD/ Pza | H30: — sin marcar | I30: NO | K30: FM-MOP-0023-DR Formato de Kaizen -R3 (_Fannie Grettelle Agu.xlsx
A31: 29 | B31: Ruben Alejandro Siller Valverde | C31: Planta 6/7 | D31: B. Números sin total en $ | F31: 0 | G31: Rutas | H31: — sin marcar | I31: — | K31: Copy of FM-MOP-0023-DR Formato de Kaizen -JUL_Ruben Alejandro Sill.xlsx
A32: 25 | B32: Jose Gerardo Gudiño Ruiz | C32: Planta 1 | D32: B. Números sin total en $ | E32: 0 | F32: 0 | G32: Total | H32: — sin marcar | I32: — | K32: FM-MOP-0023-DR Formato de Kaizen junio 26_Jose Gerardo Gudiño.xlsx
A33: 45 | B33: Adrian Rodrigues Campos | C33: Planta 6/7 | D33: B. Números sin total en $ | G33: $ | H33: — sin marcar | I33: — | J33: Cartonera P7 | K33: FM-MOP-0023-DR Formato de Kaizen - Equipos mó_Adrian Rodrigues Cam.xlsx
A34: 11 | B34: Monica Arcelia Sifuentes Ortiz | C34: Planta 2 | D34: B. Números sin total en $ | G34: N/A | H34: — sin marcar | I34: SI | J34: N/A | K34: FM-MOP-0023-DR Formato de Kaizen -R3 (003)_Monica Arcelia Sifue.xlsx
A35: 21 | B35: Arsenio Vazquez | C35: Planta 1 | D35: B. Números sin total en $ | G35: Total | H35: — sin marcar | I35: — | K35: FM-MOP-0023-DR Formato de Kaizen -R3 (1)_Arsenio Vazquez.xlsx
A36: 52 | B36: Teresita Gallegos | C36: Planta 3/4 | D36: B. Números sin total en $ | G36: Seg. | H36: — sin marcar | I36: NO | K36: FM-MOP-0023-DR Formato de Kaizen -R3 (1)_Teresita Gallegos.xlsx
A37: 9 | B37: Brandon Alejandro Duran Rios | C37: Planta 1 | D37: B. Números sin total en $ | F37: 0 | G37: USD | H37: — sin marcar | I37: — | K37: FM-MOP-0023-DR Formato de Kaizen -R3 1 JUNIO_Brandon Alejandro Du.xlsx
A38: 4 | B38: Tania Alejandra Lira Villarreal | C38: Planta 3/4 | D38: B. Números sin total en $ | G38: USD | H38: — sin marcar | I38: — | K38: FM-MOP-0023-DR Formato de Kaizen -R3 1 LOGIST_Tania Alejandra Lira.xlsx
A39: 84 | B39: Ricardo Mendoza Hernandez | C39: Planta 2 | D39: B. Números sin total en $ | G39: USD | H39: — sin marcar | I39: NO | J39: N/A | K39: FM-MOP-0023-DR Formato de Kaizen -R3 Cambio d_Ricardo Mendoza Hern 1.xlsx
A40: 47 | B40: Ricardo Mendoza Hernandez | C40: Planta 2 | D40: B. Números sin total en $ | G40: USD | H40: — sin marcar | I40: NO | J40: N/A | K40: FM-MOP-0023-DR Formato de Kaizen -R3 Cambio d_Ricardo Mendoza Hern.xlsx
A41: 56 | B41: Alejandra Natali Puente Vielma | C41: Parras | D41: B. Números sin total en $ | G41: KM | H41: — sin marcar | I41: — | K41: FM-MOP-0023-DR Formato de Kaizen -R3 Natali P_Alejandra Natali Pue.xlsx
A42: 66 | B42: Anayeli Rivera | C42: Planta 2 | D42: B. Números sin total en $ | G42: Total | H42: — sin marcar | I42: — | K42: FM-MOP-0023-DR Formato de Kaizen -R3 prov_Anayeli Rivera.xlsx
A43: 46 | B43: Berenice Esquivel Delgadillo | C43: Planta 6/7 | D43: B. Números sin total en $ | G43: 3.66 | H43: — sin marcar | I43: — | J43: Frame SUV | K43: FM-MOP-0023-DR Formato de Kaizen -R3_Berenice Esquivel De.xlsx
A44: 74 | B44: Eduardo Morales Rodriguez | C44: Planta 6/7 | D44: B. Números sin total en $ | G44: 307.0539419087137 | H44: — sin marcar | I44: — | K44: FM-MOP-0023-DR Formato de Kaizen -R3_Eduardo Morales Rodr.xlsx
A45: 23 | B45: Fannie Grettelle Aguilar Valero | C45: Planta 1 | D45: B. Números sin total en $ | G45: Segundos | H45: — sin marcar | I45: NO | K45: FM-MOP-0023-DR Formato de Kaizen -R3_Fannie Grettelle Agu.xlsx
...

Sheet Salón del Ahorro
A1: SALÓN DEL AHORRO
A2: Reconocimiento aparte del ranking de DaiPuntos. Aquí van los Kaizen con ahorro en pesos.
A3: Solo los marcados VALIDADO cuentan para el total que se reporta a Dirección. El estado lo cambias tú (columna azul).
A5: # | B5: Persona | C5: Planta | D5: Depto | E5: Ahorro MXN/año | F5: Estado | G5: Evidencia en su formato | H5: El Kaizen
A6: 1 | B6: Ricardo Mendoza Hernandez | C6: Planta 2 | D6: Materiales | E6: 644569 | F6: Pendiente | G6: Formato declara 37,915.84 USD/año — convertido a MXN @17 | H6: Ahorro anual de $37915.84 USD
A7: 2 | B7: Tania Alejandra Lira Villarreal | C7: Planta 3/4 | D7: Logística | E7: 474000 | F7: Pendiente | G7: Su formato NO trae cifras (unidades 'USD','Total' sin valor) | H7: COSTOS FIJOS POR PERIODOS DE 3 MESES
A8: 3 | B8: Federico Alberto Obispo Florencio | C8: Planta 2 | D8: Calidad | E8: 438000 | F8: Pendiente | G8: Su formato NO trae ninguna cifra | Líder real; lo registró Jose Emmanuel Alejo Wong | H8: Se implementa una lampara para la inspeccion visual y deteccion de presencia de componentes del cargador
A9: 4 | B9: Tania Alejandra Lira Villarreal | C9: Planta 6/7 | D9: Logística | E9: 438000 | F9: Pendiente | G9: Su formato dice B=474,000 C=552,000 MXN — el costo SUPERA al beneficio | H9: LICITACION PROVEEDORES EXTERNOS
A10: 5 | B10: Daniel Alejandro Parra Mendoza | C10: Parras | D10: EHS | E10: 438000 | F10: Pendiente | G10: Su formato NO trae ninguna cifra | H10: SE ESTANDARIZO EL AREA DE DISPOSICION DE QUIMICOS PELIGROSOS DEL PROCESO DE FOAM
A11: 6 | B11: Tania Alejandra Lira Villarreal | C11: Planta 3/4 | D11: Logística | E11: 288000 | F11: Pendiente | G11: Su formato dice B=438,000 C=510,000 MXN — el costo SUPERA al beneficio | H11: LICITACION PROVEEDORES EXTERNOS
A12: 7 | B12: Fannie Aguilar | C12: Planta 1 | D12: Lanzamientos | E12: 208420 | F12: Pendiente | G12: Formato con Ahorro al año lleno: 12,260 USD/año — convertido @17 | H12: Se desarrolló una fuente alternativa en China, validada para el programa, con un costo de $0.60 USD por pieza, generando un ahorro de $6.13 USD por pieza.
A13: 8 | B13: Ricardo Mendoza Hernandez | C13: Planta 2 | D13: Materiales | E13: 18173 | F13: Pendiente | G13: Formato declara 1,069 USD/año — convertido a MXN @17 | H13: Ahorro anual de $1,069 USD
D15: TOTAL DECLARADO | E15: =SUM(E6:E13) -> 2947162
D16: TOTAL VALIDADO | E16: =SUMIF(F6:F13,"Validado",E6:E13) -> 0
A18: Escribe 'Validado' en la columna Estado cuando Finanzas firme el caso. Ese es el número que puedes llevar a Dirección.
A19: Los 5 renglones en rojo necesitan soporte: o su formato no trae cifras, o el costo declarado supera al beneficio.

Sheet Ranking
A1: RANKING INDIVIDUAL — abril a septiembre 2026
A2: Cuenta el LÍDER del Kaizen (col. "Nombre de líder" del Form), no quien lo subió. Solo matriz + bonos; los ahorros van al Salón del Ahorro.
A4: # | B4: Persona | C4: Planta | D4: Kaizen | E4: DaiPuntos | F4: Proyección anual | G4: Nivel (anual)
A5: 1 | B5: Felipe Angel Guerrero Herrera | C5: Planta 2 | D5: =COUNTIFS(Evaluación!$D$5:$D$139,$B5) -> 5 | E5: =SUMIFS(Evaluación!$N$5:$N$139,Evaluación!$D$5:$D$139,$B5) -> 1700 | F5: =E5*2 -> 3400 | G5: =IF(F5>=2500,"Platino",IF(F5>=1500,"Oro",IF(F5>=600,"Plata","Bronce"))) -> Platino
A6: 2 | B6: Saúl Antonio Gallegos Sánchez | C6: Planta 2 | D6: =COUNTIFS(Evaluación!$D$5:$D$139,$B6) -> 4 | E6: =SUMIFS(Evaluación!$N$5:$N$139,Evaluación!$D$5:$D$139,$B6) -> 1600 | F6: =E6*2 -> 3200 | G6: =IF(F6>=2500,"Platino",IF(F6>=1500,"Oro",IF(F6>=600,"Plata","Bronce"))) -> Platino
A7: 3 | B7: Tania Alejandra Lira Villarreal | C7: Planta 3/4 | D7: =COUNTIFS(Evaluación!$D$5:$D$139,$B7) -> 3 | E7: =SUMIFS(Evaluación!$N$5:$N$139,Evaluación!$D$5:$D$139,$B7) -> 1350 | F7: =E7*2 -> 2700 | G7: =IF(F7>=2500,"Platino",IF(F7>=1500,"Oro",IF(F7>=600,"Plata","Bronce"))) -> Platino
A8: 4 | B8: Ricardo Mendoza Hernandez | C8: Planta 2 | D8: =COUNTIFS(Evaluación!$D$5:$D$139,$B8) -> 3 | E8: =SUMIFS(Evaluación!$N$5:$N$139,Evaluación!$D$5:$D$139,$B8) -> 1300 | F8: =E8*2 -> 2600 | G8: =IF(F8>=2500,"Platino",IF(F8>=1500,"Oro",IF(F8>=600,"Plata","Bronce"))) -> Platino
A9: 5 | B9: Jaziel Mancilla | C9: Planta 2 | D9: =COUNTIFS(Evaluación!$D$5:$D$139,$B9) -> 5 | E9: =SUMIFS(Evaluación!$N$5:$N$139,Evaluación!$D$5:$D$139,$B9) -> 1250 | F9: =E9*2 -> 2500 | G9: =IF(F9>=2500,"Platino",IF(F9>=1500,"Oro",IF(F9>=600,"Plata","Bronce"))) -> Platino
A10: 6 | B10: Daniel Alejandro Parra Mendoza | C10: Parras | D10: =COUNTIFS(Evaluación!$D$5:$D$139,$B10) -> 3 | E10: =SUMIFS(Evaluación!$N$5:$N$139,Evaluación!$D$5:$D$139,$B10) -> 1100 | F10: =E10*2 -> 2200 | G10: =IF(F10>=2500,"Platino",IF(F10>=1500,"Oro",IF(F10>=600,"Plata","Bronce"))) -> Oro
A11: 7 | B11: Omar Alvarez | C11: Planta 3/4 | D11: =COUNTIFS(Evaluación!$D$5:$D$139,$B11) -> 3 | E11: =SUMIFS(Evaluación!$N$5:$N$139,Evaluación!$D$5:$D$139,$B11) -> 1050 | F11: =E11*2 -> 2100 | G11: =IF(F11>=2500,"Platino",IF(F11>=1500,"Oro",IF(F11>=600,"Plata","Bronce"))) -> Oro
A12: 8 | B12: Francisco Hernandez Ramirez | C12: Planta 2 | D12: =COUNTIFS(Evaluación!$D$5:$D$139,$B12) -> 3 | E12: =SUMIFS(Evaluación!$N$5:$N$139,Evaluación!$D$5:$D$139,$B12) -> 800 | F12: =E12*2 -> 1600 | G12: =IF(F12>=2500,"Platino",IF(F12>=1500,"Oro",IF(F12>=600,"Plata","Bronce"))) -> Oro
A13: 9 | B13: Eduardo Gonzalez | C13: Planta 1 | D13: =COUNTIFS(Evaluación!$D$5:$D$139,$B13) -> 2 | E13: =SUMIFS(Evaluación!$N$5:$N$139,Evaluación!$D$5:$D$139,$B13) -> 750 | F13: =E13*2 -> 1500 | G13: =IF(F13>=2500,"Platino",IF(F13>=1500,"Oro",IF(F13>=600,"Plata","Bronce"))) -> Oro
A14: 10 | B14: Karina Guadalupe Flores González | C14: Parras | D14: =COUNTIFS(Evaluación!$D$5:$D$139,$B14) -> 2 | E14: =SUMIFS(Evaluación!$N$5:$N$139,Evaluación!$D$5:$D$139,$B14) -> 750 | F14: =E14*2 -> 1500 | G14: =IF(F14>=2500,"Platino",IF(F14>=1500,"Oro",IF(F14>=600,"Plata","Bronce"))) -> Oro
A15: 11 | B15: Citlalli Ozuna | C15: Planta 3/4 | D15: =COUNTIFS(Evaluación!$D$5:$D$139,$B15) -> 4 | E15: =SUMIFS(Evaluación!$N$5:$N$139,Evaluación!$D$5:$D$139,$B15) -> 700 | F15: =E15*2 -> 1400 | G15: =IF(F15>=2500,"Platino",IF(F15>=1500,"Oro",IF(F15>=600,"Plata","Bronce"))) -> Plata
A16: 12 | B16: Juan Carlos Guerrero Lozano | C16: Planta 2 | D16: =COUNTIFS(Evaluación!$D$5:$D$139,$B16) -> 3 | E16: =SUMIFS(Evaluación!$N$5:$N$139,Evaluación!$D$5:$D$139,$B16) -> 700 | F16: =E16*2 -> 1400 | G16: =IF(F16>=2500,"Platino",IF(F16>=1500,"Oro",IF(F16>=600,"Plata","Bronce"))) -> Plata
... A92: 88 | B92: Mario Alvarado | C92: Planta 6/7 | D92: =COUNTIFS(Evaluación!$D$5:$D$139,$B92) -> 1 | E92: =SUMIFS(Evaluación!$N$5:$N$139,Evaluación!$D$5:$D$139,$B92) -> 100 | F92: =E92*2 -> 200 | G92: =IF(F92>=2500,"Platino",IF(F92>=1500,"Oro",IF(F92>=600,"Plata","Bronce"))) -> Bronce

Sheet Cambio de líder
A1: CORRECCIÓN DE ATRIBUCIÓN — LÍDER vs QUIEN REGISTRÓ
A2: Los DaiPuntos se acreditan al campo "Nombre de líder" del Form, no a la cuenta que subió el registro. El Número de Empleado del Form corresponde al líder, lo que permitió validar la asignación.
A4: ID | B4: Planta | C4: Registró en el Form | D4: Líder real (recibe los puntos) | E4: # Empleado | F4: DaiPuntos | G4: Tipo de cambio | H4: Nota
A5: 7 | B5: Planta 1 | C5: Luis Gustavo Garcia Fuentes | D5: Maria Fernanda Tovanche | E5: 3049161 | F5: 450 | G5: Los puntos cambian de persona
A6: 9 | B6: Planta 1 | C6: Brandon Alejandro Duran Rios | D6: Brandon Durán | E6: 3059699 | F6: 450 | G6: Solo se corrigió la escritura del nombre
A7: 28 | B7: Planta 1 | C7: Luis Gustavo Garcia Fuentes | D7: Monserrat Arana | E7: 3041429 | F7: 450 | G7: Los puntos cambian de persona
A8: 29 | B8: Planta 6/7 | C8: Ruben Alejandro Siller Valverde | D8: Ruben Siller | E8: 3055539 | F8: 450 | G8: Solo se corrigió la escritura del nombre
A9: 31 | B9: Planta 1 | C9: Diana Themis Zacanelles Orta | D9: Eduardo Gonzalez | E9: 3029246 | F9: 450 | G9: Los puntos cambian de persona
A10: 66 | B10: Planta 2 | C10: Anayeli Rivera | D10: Anayeli Rivera Callejas | E10: 3031203 | F10: 450 | G10: Solo se corrigió la escritura del nombre
A11: 72 | B11: Planta 3/4 | C11: Erik Aguirre Ramirez | D11: Erik Javier Aguirre Ramirez | E11: 3044202 | F11: 450 | G11: Los puntos cambian de persona | H11: Líder = quien ejecutó (criterio confirmado): coincide con quien registró
A12: 82 | B12: Planta 2 | C12: Monica Arcelia Sifuentes Ortiz | D12: Gerardo del Angel Zarate | E12: 3026520 | F12: 450 | G12: Los puntos cambian de persona
A13: 87 | B13: Planta 3/4 | C13: Fernando Gonzalez | D13: Fernando Gonzalez Delgado | E13: 3054279 | F13: 450 | G13: Solo se corrigió la escritura del nombre
A14: 94 | B14: Planta 1 | C14: Fannie Grettelle Aguilar Valero | D14: Fannie Aguilar | E14: 3053215 | F14: 450 | G14: Solo se corrigió la escritura del nombre
A15: 96 | B15: Planta 2 | C15: Francisco Daniel Charles Sanchez | D15: Francisco Daniel Charles Sanchez | E15: 3062322 | F15: 450 | G15: Los puntos cambian de persona | H15: Líder = quien ejecutó (criterio confirmado): coincide con quien registró
A16: 30 | B16: Planta 1 | C16: Jose Gerardo Gudiño Ruiz | D16: Gerardo Gudiño Ruiz | E16: 3058416 | F16: 400 | G16: Los puntos cambian de persona
A17: 42 | B17: Planta 3/4 | C17: Omar Alejandro Alvarez Charles | D17: Omar Alvarez | E17: 3067714 | F17: 400 | G17: Solo se corrigió la escritura del nombre
A18: 45 | B18: Planta 6/7 | C18: Adrian Rodrigues Campos | D18: Adrian Rodriguez Campos | E18: 3061108 | F18: 400 | G18: Solo se corrigió la escritura del nombre | H18: Mismo # de empleado en ambos registros; confirmar apellido correcto.
A19: 61 | B19: Planta 3/4 | C19: Omar Alejandro Alvarez Charles | D19: Omar Alvarez | E19: 3067714 | F19: 400 | G19: Solo se corrigió la escritura del nombre
A20: 93 | B20: Planta 2 | C20: Hector Jaziel Martinez | D20: Jaziel Mancilla | E20: 3026189 | F20: 400 | G20: Solo se corrigió la escritura del nombre | H20: Mismo # de empleado en ambos registros; confirmar apellido correcto.
A21: 10 | B21: Planta 2 | C21: Carlos Lozano | D21: Juan Carlos Guerrero Lozano | E21: 3038990 | F21: 300 | G21: Los puntos cambian de persona
A22: 11 | B22: Planta 2 | C22: Monica Arcelia Sifuentes Ortiz | D22: Monica Sifuentes Ortiz | E22: 3065185 | F22: 300 | G22: Solo se corrigió la escritura del nombre
A23: 24 | B23: Planta 1 | C23: Mariana Valencia | D23: Jose Isai Tostado Beltran | E23: 3024217 | F23: 300 | G23: Los puntos cambian de persona
A24: 26 | B24: Planta 1 | C24: Ulises Eduardo Hernandez Perez | D24: Ulises Hernandez | E24: 3055561 | F24: 300 | G24: Solo se corrigió la escritura del nombre
A25: 33 | B25: Planta 2 | C25: Francisco Hernandez | D25: Francisco Hernandez Ramirez | E25: 3055346 | F25: 300 | G25: Solo se corrigió la escritura del nombre
A26: 34 | B26: Planta 2 | C26: Monica Arcelia Sifuentes Ortiz | D26: Monica Sifuentes Ortiz | E26: 3065185 | F26: 300 | G26: Solo se corrigió la escritura del nombre
A27: 46 | B27: Planta 6/7 | C27: Berenice Esquivel Delgadillo | D27: Berenice Esquivel | E27: 3027573 | F27: 300 | G27: Solo se corrigió la escritura del nombre
A28: 51 | B28: Parras | C28: Fernanda Monserrath Vielma Zavala | D28: Luis Reyes | E28: 3066350 | F28: 300 | G28: Los puntos cambian de persona
A29: 53 | B29: Planta 3/4 | C29: Karla Guadalupe Padilla Gonzalez | D29: Marco Rodríguez | E29: 3030351 | F29: 300 | G29: Los puntos cambian de persona
A30: 54 | B30: Planta 1 | C30: Ensamble Produccion | D30: Citlali Nalleli Garza Hernandez | E30: 3042836 | F30: 300 | G30: Los puntos cambian de persona
A31: 57 | B31: Planta 2 | C31: Jose Emmanuel Alejo Wong | D31: Federico Alberto Obispo Florencio | E31: 3039850 | F31: 300 | G31: Los puntos cambian de persona
A32: 58 | B32: Planta 2 | C32: Hector Jaziel Martinez | D32: Jaziel Mancilla | E32: 3026189 | F32: 300 | G32: Solo se corrigió la escritura del nombre | H32: Mismo # de empleado en ambos registros; confirmar apellido correcto.
A33: 59 | B33: Planta 2 | C33: Hector Jaziel Martinez | D33: Jaziel Mancilla | E33: 3026189 | F33: 300 | G33: Solo se corrigió la escritura del nombre | H33: Mismo # de empleado en ambos registros; confirmar apellido correcto.
A34: 62 | B34: Planta 6/7 | C34: Gustavo Vargas Quiroz | D34: Gustavo Vargas | E34: 3061983 | F34: 300 | G34: Solo se corrigió la escritura del nombre
A35: 63 | B35: Planta 1 | C35: Miguel Eduardo Villegas Prieto | D35: Miguel Villegas | E35: 3055580 | F35: 300 | G35: Solo se corrigió la escritura del nombre
A36: 68 | B36: Planta 2 | C36: Francisco Hernandez | D36: Francisco Hernandez Ramirez | E36: 3055346 | F36: 300 | G36: Solo se corrigió la escritura del nombre
A37: 69 | B37: Planta 1 | C37: Diana Themis Zacanelles Orta | D37: Eduardo Gonzalez | E37: 3029246 | F37: 300 | G37: Los puntos cambian de persona
A38: 74 | B38: Planta 6/7 | C38: Eduardo Morales Rodriguez | D38: Alejandro Caseres | E38: 3031856 | F38: 300 | G38: Los puntos cambian de persona
A39: 78 | B39: Planta 1 | C39: Jose Ignacio Arias Palacios | D39: Nestor Estrada | E39: 3044346 | F39: 300 | G39: Los puntos cambian de persona
A40: 79 | B40: Planta 1 | C40: Ensamble Produccion | D40: Luis Gerardo Rivera Salazar | E40: 1680380 | F40: 300 | G40: Los puntos cambian de persona
A41: 86 | B41: Parras | C41: Brandon Ramon Cano Resendez | D41: Hugo Alcalá | E41: 3056806 | F41: 300 | G41: Los puntos cambian de persona
...

Sheet Nuevos (provisional)
A1: NUEVOS KAIZEN (carpeta Question (1)) — EVALUACIÓN PROVISIONAL
A2: Provisional: planta/depto/líder salen de los archivos, no del Form (el concentrado está desactualizado). Impacto y alcance son mi lectura del archivo. No se han subido al dashboard. 'Cuenta' = Sí / Dudoso / No.
A4: ID | B4: Autor del archivo | C4: Planta / Depto | D4: Kaizen | E4: Líder / firmantes (por confirmar) | F4: Fecha impl. | G4: Estatus | H4: Indicador | I4: IMPACTO | J4: ALCANCE | K4: Ahorro declarado MXN (informativo) | L4: Pts matriz | M4: Bono seg. | N4: TOTAL (si Cuenta=Sí) | O4: Cuenta | P4: Banderas
